Workbook

Sheet Отдел Продаж МП  
A1: 12 | B1: Фамилия Имя | C1: Регион | D1: Должность | E1: Срок командировки | F1: Транспорт (Авиа, Ж/д, авто) | G1: Город проживания-Город командировок-Город проживания | H1: КМ | I1: Кол-во аптек (для МП) | J1: согласование от РД | K1: согласование от ДП | L1: Цель | M1: Действие | N1: Ожидаемый Результат | O1: Число отправления из города | P1: Время отправления из города | Q1: Число прибытия в командировочный город | R1: Время прибытия в командировочный город | S1: Число убытия из командировочного города | T1: Время убытия из командировочного города | U1: Число прибытия в город | V1: Время прибытия в город | W1: Комментарии | X1: Заказ гостиницы Да/Нет | Y1: Город командировки | Z1: Название гостиницы | AA1: Ссылка для выбора гостиниц | AB1: Комментарии | AC1: Заказ Билетов Да/Нет | AD1: Город(а) | AE1: Ориентировочное время - когда надо ехать (туда) | AF1: Ориентировочное время - когда надо ехать (обратно) | AG1: Дней | AH1: ночи | AI1: суточные (норма) | AJ1: Итог суточные
B2: Кузнецова Марина Борисовна | C2: =IFERROR(VLOOKUP(B2,Инфо!$A$2:$E$89,4,0),"") -> Сибирский | D2: =IFERROR(VLOOKUP($B2,Инфо!$A$3:$E$91,5,0),"") -> Медицинский представитель ОТС | E2: =IFERROR(IF(B2=0,"",IF(O2=U2,CONCATENATE(O2," ",VLOOKUP($A$1,Инфо!$K:$M,3,0)),CONCATENATE(O2,"-",U2," ",VLOOKUP($A$1,Инфо!$K:$M,3,0)))),"") -> 8 декабря | F2: авто | G2: Иркутск - Ангарск - Усолье-Сибирское - Иркутск | H2: =IF(F2="авто",VLOOKUP(G2,'Расстояние между городами'!C:D,2,0),"") -> 156 | I2: 12 | J2: Согласовано | K2: Согласовано | L2: выполнение плана 4Q | M2: выполнение плана 4Q | N2: выполнение плана 4Q | O2: 8 | P2: 0.33333333 | Q2: 8 | R2: 0.41666667 | S2: 8 | T2: 0.70833333 | U2: 8 | V2: 0.79166667 | AG2: =IF(V2=0,"",AH2+1) -> 1 | AH2: =U2-O2 -> 0 | AI2: =IFERROR(IF(AG2=0,"",VLOOKUP($D2,Суточные!$A$2:$C$13,3,0)),"") -> 1700 | AJ2: =IFERROR(IF(AG2>1,AG2*AI2,IF(AND(AG2=1,OR(F2="ж/д",F2="авиа")),AG2*AI2,0)),"") -> 0
B3: Кузнецова Марина Борисовна | C3: =IFERROR(VLOOKUP(B3,Инфо!$A$2:$E$89,4,0),"") -> Сибирский | D3: =IFERROR(VLOOKUP($B3,Инфо!$A$3:$E$91,5,0),"") -> Медицинский представитель ОТС | E3: =IFERROR(IF(B3=0,"",IF(O3=U3,CONCATENATE(O3," ",VLOOKUP($A$1,Инфо!$K:$M,3,0)),CONCATENATE(O3,"-",U3," ",VLOOKUP($A$1,Инфо!$K:$M,3,0)))),"") -> 9 декабря | F3: авто | G3: Иркутск - Шелехов - Иркутск | H3: =IF(F3="авто",VLOOKUP(G3,'Расстояние между городами'!C:D,2,0),"") -> 38 | I3: 12 | J3: Согласовано | K3: Согласовано | L3: выполнение плана 4Q | M3: выполнение плана 4Q | N3: выполнение плана 4Q | O3: 9 | P3: 0.33333333 | Q3: 9 | R3: 0.375 | S3: 9 | T3: 0.70833333 | U3: 9 | V3: 0.75 | AG3: =IF(V3=0,"",AH3+1) -> 1 | AH3: =U3-O3 -> 0 | AI3: =IFERROR(IF(AG3=0,"",VLOOKUP($D3,Суточные!$A$2:$C$13,3,0)),"") -> 1700 | AJ3: =IFERROR(IF(AG3>1,AG3*AI3,IF(AND(AG3=1,OR(F3="ж/д",F3="авиа")),AG3*AI3,0)),"") -> 0
B4: Кузнецова Марина Борисовна | C4: =IFERROR(VLOOKUP(B4,Инфо!$A$2:$E$89,4,0),"") -> Сибирский | D4: =IFERROR(VLOOKUP($B4,Инфо!$A$3:$E$91,5,0),"") -> Медицинский представитель ОТС | E4: =IFERROR(IF(B4=0,"",IF(O4=U4,CONCATENATE(O4," ",VLOOKUP($A$1,Инфо!$K:$M,3,0)),CONCATENATE(O4,"-",U4," ",VLOOKUP($A$1,Инфо!$K:$M,3,0)))),"") -> 12 декабря | F4: авто | G4: Иркутск - Хомутово-Урик - Иркутск | H4: =IF(F4="авто",VLOOKUP(G4,'Расстояние между городами'!C:D,2,0),"") -> 66 | I4: 12 | J4: Согласовано | K4: Согласовано | L4: выполнение плана 4Q | M4: выполнение плана 4Q | N4: выполнение плана 4Q | O4: 12 | P4: 0.33333333 | Q4: 12 | R4: 0.375 | S4: 12 | T4: 0.70833333 | U4: 12 | V4: 0.75 | AG4: =IF(V4=0,"",AH4+1) -> 1 | AH4: =U4-O4 -> 0 | AI4: =IFERROR(IF(AG4=0,"",VLOOKUP($D4,Суточные!$A$2:$C$13,3,0)),"") -> 1700 | AJ4: =IFERROR(IF(AG4>1,AG4*AI4,IF(AND(AG4=1,OR(F4="ж/д",F4="авиа")),AG4*AI4,0)),"") -> 0
B5: Кузнецова Марина Борисовна | C5: =IFERROR(VLOOKUP(B5,Инфо!$A$2:$E$89,4,0),"") -> Сибирский | D5: =IFERROR(VLOOKUP($B5,Инфо!$A$3:$E$91,5,0),"") -> Медицинский представитель ОТС | E5: =IFERROR(IF(B5=0,"",IF(O5=U5,CONCATENATE(O5," ",VLOOKUP($A$1,Инфо!$K:$M,3,0)),CONCATENATE(O5,"-",U5," ",VLOOKUP($A$1,Инфо!$K:$M,3,0)))),"") -> 22 декабря | F5: авто | G5: Иркутск - Ангарск - Усолье-Сибирское - Иркутск | H5: =IF(F5="авто",VLOOKUP(G5,'Расстояние между городами'!C:D,2,0),"") -> 156 | I5: 12 | J5: Согласовано | K5: Согласовано | L5: выполнение плана 4Q | M5: выполнение плана 4Q | N5: выполнение плана 4Q | O5: 22 | P5: 0.33333333 | Q5: 22 | R5: 0.41666667 | S5: 22 | T5: 0.70833333 | U5: 22 | V5: 0.79166667 | AG5: =IF(V5=0,"",AH5+1) -> 1 | AH5: =U5-O5 -> 0 | AI5: =IFERROR(IF(AG5=0,"",VLOOKUP($D5,Суточные!$A$2:$C$13,3,0)),"") -> 1700 | AJ5: =IFERROR(IF(AG5>1,AG5*AI5,IF(AND(AG5=1,OR(F5="ж/д",F5="авиа")),AG5*AI5,0)),"") -> 0
B6: Кузнецова Марина Борисовна | C6: =IFERROR(VLOOKUP(B6,Инфо!$A$2:$E$89,4,0),"") -> Сибирский | D6: =IFERROR(VLOOKUP($B6,Инфо!$A$3:$E$91,5,0),"") -> Медицинский представитель ОТС | E6: =IFERROR(IF(B6=0,"",IF(O6=U6,CONCATENATE(O6," ",VLOOKUP($A$1,Инфо!$K:$M,3,0)),CONCATENATE(O6,"-",U6," ",VLOOKUP($A$1,Инфо!$K:$M,3,0)))),"") -> 23 декабря | F6: авто | G6: Иркутск - Шелехов - Иркутск | H6: =IF(F6="авто",VLOOKUP(G6,'Расстояние между городами'!C:D,2,0),"") -> 38 | I6: 12 | J6: Согласовано | K6: Согласовано | L6: выполнение плана 4Q | M6: выполнение плана 4Q | N6: выполнение плана 4Q | O6: 23 | P6: 0.33333333 | Q6: 23 | R6: 0.375 | S6: 23 | T6: 0.70833333 | U6: 23 | V6: 0.75 | AG6: =IF(V6=0,"",AH6+1) -> 1 | AH6: =U6-O6 -> 0 | AI6: =IFERROR(IF(AG6=0,"",VLOOKUP($D6,Суточные!$A$2:$C$13,3,0)),"") -> 1700 | AJ6: =IFERROR(IF(AG6>1,AG6*AI6,IF(AND(AG6=1,OR(F6="ж/д",F6="авиа")),AG6*AI6,0)),"") -> 0
B7: Кузнецова Марина Борисовна | C7: =IFERROR(VLOOKUP(B7,Инфо!$A$2:$E$89,4,0),"") -> Сибирский | D7: =IFERROR(VLOOKUP($B7,Инфо!$A$3:$E$91,5,0),"") -> Медицинский представитель ОТС | E7: =IFERROR(IF(B7=0,"",IF(O7=U7,CONCATENATE(O7," ",VLOOKUP($A$1,Инфо!$K:$M,3,0)),CONCATENATE(O7,"-",U7," ",VLOOKUP($A$1,Инфо!$K:$M,3,0)))),"") -> 26 декабря | F7: авто | G7: Иркутск - Хомутово-Урик - Иркутск | H7: =IF(F7="авто",VLOOKUP(G7,'Расстояние между городами'!C:D,2,0),"") -> 66 | I7: 12 | J7: Согласовано | K7: Согласовано | L7: выполнение плана 4Q | M7: выполнение плана 4Q | N7: выполнение плана 4Q | O7: 26 | P7: 0.33333333 | Q7: 26 | R7: 0.375 | S7: 26 | T7: 0.70833333 | U7: 26 | V7: 0.75 | AG7: =IF(V7=0,"",AH7+1) -> 1 | AH7: =U7-O7 -> 0 | AI7: =IFERROR(IF(AG7=0,"",VLOOKUP($D7,Суточные!$A$2:$C$13,3,0)),"") -> 1700 | AJ7: =IFERROR(IF(AG7>1,AG7*AI7,IF(AND(AG7=1,OR(F7="ж/д",F7="авиа")),AG7*AI7,0)),"") -> 0
B8: Чураева Марина Олеговна | C8: =IFERROR(VLOOKUP(B8,Инфо!$A$2:$E$89,4,0),"") -> Волжский | D8: =IFERROR(VLOOKUP($B8,Инфо!$A$3:$E$91,5,0),"") -> Медицинский представитель ОТС | E8: =IFERROR(IF(B8=0,"",IF(O8=U8,CONCATENATE(O8," ",VLOOKUP($A$1,Инфо!$K:$M,3,0)),CONCATENATE(O8,"-",U8," ",VLOOKUP($A$1,Инфо!$K:$M,3,0)))),"") -> 4-5 декабря | F8: авто | G8: Пенза - Саранск - Пенза | H8: =IF(F8="авто",VLOOKUP(G8,'Расстояние между городами'!C:D,2,0),"") -> 297 | I8: 12 | J8: Согласовано | L8: выполнение плана 4Q | M8: выполнение плана 4Q | N8: выполнение плана 4Q | O8: 4 | P8: 0.33333333 | Q8: 4 | R8: 0.41666667 | S8: 5 | T8: 0.66666667 | U8: 5 | V8: 0.75 | AG8: =IF(V8=0,"",AH8+1) -> 2 | AH8: =U8-O8 -> 1 | AI8: =IFERROR(IF(AG8=0,"",VLOOKUP($D8,Суточные!$A$2:$C$13,3,0)),"") -> 1700 | AJ8: =IFERROR(IF(AG8>1,AG8*AI8,IF(AND(AG8=1,OR(F8="ж/д",F8="авиа")),AG8*AI8,0)),"") -> 3400
B9: Чураева Марина Олеговна | C9: =IFERROR(VLOOKUP(B9,Инфо!$A$2:$E$89,4,0),"") -> Волжский | D9: =IFERROR(VLOOKUP($B9,Инфо!$A$3:$E$91,5,0),"") -> Медицинский представитель ОТС | E9: =IFERROR(IF(B9=0,"",IF(O9=U9,CONCATENATE(O9," ",VLOOKUP($A$1,Инфо!$K:$M,3,0)),CONCATENATE(O9,"-",U9," ",VLOOKUP($A$1,Инфо!$K:$M,3,0)))),"") -> 16-17 декабря | F9: авто | G9: Пенза - Саранск - Пенза | H9: =IF(F9="авто",VLOOKUP(G9,'Расстояние между городами'!C:D,2,0),"") -> 297 | I9: 12 | L9: выполнение плана 4Q | M9: выполнение плана 4Q | N9: выполнение плана 4Q | O9: 16 | P9: 0.33333333 | Q9: 16 | R9: 0.41666667 | S9: 17 | T9: 0.66666667 | U9: 17 | V9: 0.75 | AG9: =IF(V9=0,"",AH9+1) -> 2 | AH9: =U9-O9 -> 1 | AI9: =IFERROR(IF(AG9=0,"",VLOOKUP($D9,Суточные!$A$2:$C$13,3,0)),"") -> 1700 | AJ9: =IFERROR(IF(AG9>1,AG9*AI9,IF(AND(AG9=1,OR(F9="ж/д",F9="авиа")),AG9*AI9,0)),"") -> 3400
B10: Шарыпов Александр Александрович | C10: =IFERROR(VLOOKUP(B10,Инфо!$A$2:$E$89,4,0),"") -> Сибирский | D10: =IFERROR(VLOOKUP($B10,Инфо!$A$3:$E$91,5,0),"") -> Медицинский представитель ОТС | E10: =IFERROR(IF(B10=0,"",IF(O10=U10,CONCATENATE(O10," ",VLOOKUP($A$1,Инфо!$K:$M,3,0)),CONCATENATE(O10,"-",U10," ",VLOOKUP($A$1,Инфо!$K:$M,3,0)))),"") -> 2 декабря | F10: авто | G10: Новосибирск - Искитим - Линёво - Новосибирск | H10: =IF(F10="авто",VLOOKUP(G10,'Расстояние между городами'!C:D,2,0),"") -> 160 | I10: 12 | L10: выполнение плана 4Q | M10: выполнение плана 4Q | N10: выполнение плана 4Q | O10: 2 | P10: 0.33333333 | Q10: 2 | R10: 0.41666667 | S10: 2 | T10: 0.66666667 | U10: 2 | V10: 0.75 | AG10: =IF(V10=0,"",AH10+1) -> 1 | AH10: =U10-O10 -> 0 | AI10: =IFERROR(IF(AG10=0,"",VLOOKUP($D10,Суточные!$A$2:$C$13,3,0)),"") -> 1700 | AJ10: =IFERROR(IF(AG10>1,AG10*AI10,IF(AND(AG10=1,OR(F10="ж/д",F10="авиа")),AG10*AI10,0)),"") -> 0
B11: Шарыпов Александр Александрович | C11: =IFERROR(VLOOKUP(B11,Инфо!$A$2:$E$89,4,0),"") -> Сибирский | D11: =IFERROR(VLOOKUP($B11,Инфо!$A$3:$E$91,5,0),"") -> Медицинский представитель ОТС | E11: =IFERROR(IF(B11=0,"",IF(O11=U11,CONCATENATE(O11," ",VLOOKUP($A$1,Инфо!$K:$M,3,0)),CONCATENATE(O11,"-",U11," ",VLOOKUP($A$1,Инфо!$K:$M,3,0)))),"") -> 4 декабря | F11: авто | G11: Новосибирск - Бердск - Новосибирск | H11: =IF(F11="авто",VLOOKUP(G11,'Расстояние между городами'!C:D,2,0),"") -> 75 | I11: 12 | L11: выполнение плана 4Q | M11: выполнение плана 4Q | N11: выполнение плана 4Q | O11: 4 | P11: 0.33333333 | Q11: 4 | R11: 0.41666667 | S11: 4 | T11: 0.66666667 | U11: 4 | V11: 0.75 | AG11: =IF(V11=0,"",AH11+1) -> 1 | AH11: =U11-O11 -> 0 | AI11: =IFERROR(IF(AG11=0,"",VLOOKUP($D11,Суточные!$A$2:$C$13,3,0)),"") -> 1700 | AJ11: =IFERROR(IF(AG11>1,AG11*AI11,IF(AND(AG11=1,OR(F11="ж/д",F11="авиа")),AG11*AI11,0)),"") -> 0
B12: Шарыпов Александр Александрович | C12: =IFERROR(VLOOKUP(B12,Инфо!$A$2:$E$89,4,0),"") -> Сибирский | D12: =IFERROR(VLOOKUP($B12,Инфо!$A$3:$E$91,5,0),"") -> Медицинский представитель ОТС | E12: =IFERROR(IF(B12=0,"",IF(O12=U12,CONCATENATE(O12," ",VLOOKUP($A$1,Инфо!$K:$M,3,0)),CONCATENATE(O12,"-",U12," ",VLOOKUP($A$1,Инфо!$K:$M,3,0)))),"") -> 11 декабря | F12: авто | G12: Новосибирск - Бердск - Новосибирск | H12: =IF(F12="авто",VLOOKUP(G12,'Расстояние между городами'!C:D,2,0),"") -> 75 | I12: 12 | L12: выполнение плана 4Q | M12: выполнение плана 4Q | N12: выполнение плана 4Q | O12: 11 | P12: 0.33333333 | Q12: 11 | R12: 0.41666667 | S12: 11 | T12: 0.66666667 | U12: 11 | V12: 0.75 | AG12: =IF(V12=0,"",AH12+1) -> 1 | AH12: =U12-O12 -> 0 | AI12: =IFERROR(IF(AG12=0,"",VLOOKUP($D12,Суточные!$A$2:$C$13,3,0)),"") -> 1700 | AJ12: =IFERROR(IF(AG12>1,AG12*AI12,IF(AND(AG12=1,OR(F12="ж/д",F12="авиа")),AG12*AI12,0)),"") -> 0
B13: Шарыпов Александр Александрович | C13: =IFERROR(VLOOKUP(B13,Инфо!$A$2:$E$89,4,0),"") -> Сибирский | D13: =IFERROR(VLOOKUP($B13,Инфо!$A$3:$E$91,5,0),"") -> Медицинский представитель ОТС | E13: =IFERROR(IF(B13=0,"",IF(O13=U13,CONCATENATE(O13," ",VLOOKUP($A$1,Инфо!$K:$M,3,0)),CONCATENATE(O13,"-",U13," ",VLOOKUP($A$1,Инфо!$K:$M,3,0)))),"") -> 16 декабря | F13: авто | G13: Новосибирск - Искитим - Линёво - Новосибирск | H13: =IF(F13="авто",VLOOKUP(G13,'Расстояние между городами'!C:D,2,0),"") -> 160 | I13: 12 | L13: выполнение плана 4Q | M13: выполнение плана 4Q | N13: выполнение плана 4Q | O13: 16 | P13: 0.33333333 | Q13: 16 | R13: 0.41666667 | S13: 16 | T13: 0.66666667 | U13: 16 | V13: 0.75 | AG13: =IF(V13=0,"",AH13+1) -> 1 | AH13: =U13-O13 -> 0 | AI13: =IFERROR(IF(AG13=0,"",VLOOKUP($D13,Суточные!$A$2:$C$13,3,0)),"") -> 1700 | AJ13: =IFERROR(IF(AG13>1,AG13*AI13,IF(AND(AG13=1,OR(F13="ж/д",F13="авиа")),AG13*AI13,0)),"") -> 0
B14: Шарыпов Александр Александрович | C14: =IFERROR(VLOOKUP(B14,Инфо!$A$2:$E$89,4,0),"") -> Сибирский | D14: =IFERROR(VLOOKUP($B14,Инфо!$A$3:$E$91,5,0),"") -> Медицинский представитель ОТС | E14: =IFERROR(IF(B14=0,"",IF(O14=U14,CONCATENATE(O14," ",VLOOKUP($A$1,Инфо!$K:$M,3,0)),CONCATENATE(O14,"-",U14," ",VLOOKUP($A$1,Инфо!$K:$M,3,0)))),"") -> 18 декабря | F14: авто | G14: Новосибирск - Бердск - Новосибирск | H14: =IF(F14="авто",VLOOKUP(G14,'Расстояние между городами'!C:D,2,0),"") -> 75 | I14: 12 | L14: выполнение плана 4Q | M14: выполнение плана 4Q | N14: выполнение плана 4Q | O14: 18 | P14: 0.33333333 | Q14: 18 | R14: 0.41666667 | S14: 18 | T14: 0.66666667 | U14: 18 | V14: 0.75 | AG14: =IF(V14=0,"",AH14+1) -> 1 | AH14: =U14-O14 -> 0 | AI14: =IFERROR(IF(AG14=0,"",VLOOKUP($D14,Суточные!$A$2:$C$13,3,0)),"") -> 1700 | AJ14: =IFERROR(IF(AG14>1,AG14*AI14,IF(AND(AG14=1,OR(F14="ж/д",F14="авиа")),AG14*AI14,0)),"") -> 0
B15: Шарыпов Александр Александрович | C15: =IFERROR(VLOOKUP(B15,Инфо!$A$2:$E$89,4,0),"") -> Сибирский | D15: =IFERROR(VLOOKUP($B15,Инфо!$A$3:$E$91,5,0),"") -> Медицинский представитель ОТС | E15: =IFERROR(IF(B15=0,"",IF(O15=U15,CONCATENATE(O15," ",VLOOKUP($A$1,Инфо!$K:$M,3,0)),CONCATENATE(O15,"-",U15," ",VLOOKUP($A$1,Инфо!$K:$M,3,0)))),"") -> 25 декабря | F15: авто | G15: Новосибирск - Бердск - Новосибирск | H15: =IF(F15="авто",VLOOKUP(G15,'Расстояние между городами'!C:D,2,0),"") -> 75 | I15: 12 | L15: выполнение плана 4Q | M15: выполнение плана 4Q | N15: выполнение плана 4Q | O15: 25 | P15: 0.33333333 | Q15: 25 | R15: 0.41666667 | S15: 25 | T15: 0.66666667 | U15: 25 | V15: 0.75 | AG15: =IF(V15=0,"",AH15+1) -> 1 | AH15: =U15-O15 -> 0 | AI15: =IFERROR(IF(AG15=0,"",VLOOKUP($D15,Суточные!$A$2:$C$13,3,0)),"") -> 1700 | AJ15: =IFERROR(IF(AG15>1,AG15*AI15,IF(AND(AG15=1,OR(F15="ж/д",F15="авиа")),AG15*AI15,0)),"") -> 0
B16: Молчанова Надежда Николаевна | C16: =IFERROR(VLOOKUP(B16,Инфо!$A$2:$E$89,4,0),"") -> Сибирский | D16: =IFERROR(VLOOKUP($B16,Инфо!$A$3:$E$91,5,0),"") -> Медицинский представитель ОТС | E16: =IFERROR(IF(B16=0,"",IF(O16=U16,CONCATENATE(O16," ",VLOOKUP($A$1,Инфо!$K:$M,3,0)),CONCATENATE(O16,"-",U16," ",VLOOKUP($A$1,Инфо!$K:$M,3,0)))),"") -> 9-11 декабря | F16: авто | G16: Барнаул - Бийск - Барнаул | H16: =IF(F16="авто",VLOOKUP(G16,'Расстояние между городами'!C:D,2,0),"") -> 319 | I16: 34 | J16: Согласовано | K16: Согласовано | L16: выполнение плана 4Q | M16: выполнение плана 4Q | N16: выполнение плана 4Q | O16: 9 | P16: 0.29166667 | Q16: 9 | R16: 0.375 | S16: 11 | T16: 0.66666667 | U16: 11 | V16: 0.75 | AG16: =IF(V16=0,"",AH16+1) -> 3 | AH16: =U16-O16 -> 2 | AI16: =IFERROR(IF(AG16=0,"",VLOOKUP($D16,Суточные!$A$2:$C$13,3,0)),"") -> 1700 | AJ16: =IFERROR(IF(AG16>1,AG16*AI16,IF(AND(AG16=1,OR(F16="ж/д",F16="авиа")),AG16*AI16,0)),"") -> 5100
B17: Ласточкина Наталья Михайловна | C17: =IFERROR(VLOOKUP(B17,Инфо!$A$2:$E$89,4,0),"") -> Волжский | D17: =IFERROR(VLOOKUP($B17,Инфо!$A$3:$E$91,5,0),"") -> Медицинский представитель ОТС | E17: =IFERROR(IF(B17=0,"",IF(O17=U17,CONCATENATE(O17," ",VLOOKUP($A$1,Инфо!$K:$M,3,0)),CONCATENATE(O17,"-",U17," ",VLOOKUP($A$1,Инфо!$K:$M,3,0)))),"") -> 2 декабря | F17: авто | G17: Чебоксары - Канаш - Чебоксары | H17: =IF(F17="авто",VLOOKUP(G17,'Расстояние между городами'!C:D,2,0),"") -> 164 | I17: 12 | L17: выполнение плана 4Q | M17: выполнение плана 4Q | N17: выполнение плана 4Q | O17: 2 | P17: 0.33333333 | Q17: 2 | R17: 0.375 | S17: 2 | T17: 0.66666667 | U17: 2 | V17: 0.75 | AG17: =IF(V17=0,"",AH17+1) -> 1 | AH17: =U17-O17 -> 0 | AI17: =IFERROR(IF(AG17=0,"",VLOOKUP($D17,Суточные!$A$2:$C$13,3,0)),"") -> 1700 | AJ17: =IFERROR(IF(AG17>1,AG17*AI17,IF(AND(AG17=1,OR(F17="ж/д",F17="авиа")),AG17*AI17,0)),"") -> 0
B18: Ласточкина Наталья Михайловна | C18: =IFERROR(VLOOKUP(B18,Инфо!$A$2:$E$89,4,0),"") -> Волжский | D18: =IFERROR(VLOOKUP($B18,Инфо!$A$3:$E$91,5,0),"") -> Медицинский представитель ОТС | E18: =IFERROR(IF(B18=0,"",IF(O18=U18,CONCATENATE(O18," ",VLOOKUP($A$1,Инфо!$K:$M,3,0)),CONCATENATE(O18,"-",U18," ",VLOOKUP($A$1,Инфо!$K:$M,3,0)))),"") -> 4 декабря | F18: авто | G18: Чебоксары - Йошкар-Ола - Чебоксары | H18: =IF(F18="авто",VLOOKUP(G18,'Расстояние между городами'!C:D,2,0),"") -> 186 | I18: 14 | L18: выполнение плана 4Q | M18: выполнение плана 4Q | N18: выполнение плана 4Q | O18: 4 | P18: 0.29166667 | Q18: 4 | R18: 0.375 | S18: 4 | T18: 0.66666667 | U18: 4 | V18: 0.75 | AG18: =IF(V18=0,"",AH18+1) -> 1 | AH18: =U18-O18 -> 0 | AI18: =IFERROR(IF(AG18=0,"",VLOOKUP($D18,Суточные!$A$2:$C$13,3,0)),"") -> 1700 | AJ18: =IFERROR(IF(AG18>1,AG18*AI18,IF(AND(AG18=1,OR(F18="ж/д",F18="авиа")),AG18*AI18,0)),"") -> 0
B19: Ласточкина Наталья Михайловна | C19: =IFERROR(VLOOKUP(B19,Инфо!$A$2:$E$89,4,0),"") -> Волжский | D19: =IFERROR(VLOOKUP($B19,Инфо!$A$3:$E$91,5,0),"") -> Медицинский представитель ОТС | E19: =IFERROR(IF(B19=0,"",IF(O19=U19,CONCATENATE(O19," ",VLOOKUP($A$1,Инфо!$K:$M,3,0)),CONCATENATE(O19,"-",U19," ",VLOOKUP($A$1,Инфо!$K:$M,3,0)))),"") -> 11 декабря | F19: авто | G19: Чебоксары - Канаш - Чебоксары | H19: =IF(F19="авто",VLOOKUP(G19,'Расстояние между городами'!C:D,2,0),"") -> 164 | I19: 12 | L19: выполнение плана 4Q | M19: выполнение плана 4Q | N19: выполнение плана 4Q | O19: 11 | P19: 0.33333333 | Q19: 11 | R19: 0.375 | S19: 11 | T19: 0.66666667 | U19: 11 | V19: 0.75 | AG19: =IF(V19=0,"",AH19+1) -> 1 | AH19: =U19-O19 -> 0 | AI19: =IFERROR(IF(AG19=0,"",VLOOKUP($D19,Суточные!$A$2:$C$13,3,0)),"") -> 1700 | AJ19: =IFERROR(IF(AG19>1,AG19*AI19,IF(AND(AG19=1,OR(F19="ж/д",F19="авиа")),AG19*AI19,0)),"") -> 0
B20: Ласточкина Наталья Михайловна | C20: =IFERROR(VLOOKUP(B20,Инфо!$A$2:$E$89,4,0),"") -> Волжский | D20: =IFERROR(VLOOKUP($B20,Инфо!$A$3:$E$91,5,0),"") -> Медицинский представитель ОТС | E20: =IFERROR(IF(B20=0,"",IF(O20=U20,CONCATENATE(O20," ",VLOOKUP($A$1,Инфо!$K:$M,3,0)),CONCATENATE(O20,"-",U20," ",VLOOKUP($A$1,Инфо!$K:$M,3,0)))),"") -> 16 декабря | F20: авто | G20: Чебоксары - Канаш - Чебоксары | H20: =IF(F20="авто",VLOOKUP(G20,'Расстояние между городами'!C:D,2,0),"") -> 164 | I20: 12 | L20: выполнение плана 4Q | M20: выполнение плана 4Q | N20: выполнение плана 4Q | O20: 16 | P20: 0.33333333 | Q20: 16 | R20: 0.375 | S20: 16 | T20: 0.66666667 | U20: 16 | V20: 0.75 | AG20: =IF(V20=0,"",AH20+1) -> 1 | AH20: =U20-O20 -> 0 | AI20: =IFERROR(IF(AG20=0,"",VLOOKUP($D20,Суточные!$A$2:$C$13,3,0)),"") -> 1700 | AJ20: =IFERROR(IF(AG20>1,AG20*AI20,IF(AND(AG20=1,OR(F20="ж/д",F20="авиа")),AG20*AI20,0)),"") -> 0
B21: Ласточкина Наталья Михайловна | C21: =IFERROR(VLOOKUP(B21,Инфо!$A$2:$E$89,4,0),"") -> Волжский | D21: =IFERROR(VLOOKUP($B21,Инфо!$A$3:$E$91,5,0),"") -> Медицинский представитель ОТС | E21: =IFERROR(IF(B21=0,"",IF(O21=U21,CONCATENATE(O21," ",VLOOKUP($A$1,Инфо!$K:$M,3,0)),CONCATENATE(O21,"-",U21," ",VLOOKUP($A$1,Инфо!$K:$M,3,0)))),"") -> 18 декабря | F21: авто | G21: Чебоксары - Йошкар-Ола - Чебоксары | H21: =IF(F21="авто",VLOOKUP(G21,'Расстояние между городами'!C:D,2,0),"") -> 186 | I21: 14 | L21: выполнение плана 4Q | M21: выполнение плана 4Q | N21: выполнение плана 4Q | O21: 18 | P21: 0.29166667 | Q21: 18 | R21: 0.375 | S21: 18 | T21: 0.66666667 | U21: 18 | V21: 0.75 | AG21: =IF(V21=0,"",AH21+1) -> 1 | AH21: =U21-O21 -> 0 | AI21: =IFERROR(IF(AG21=0,"",VLOOKUP($D21,Суточные!$A$2:$C$13,3,0)),"") -> 1700 | AJ21: =IFERROR(IF(AG21>1,AG21*AI21,IF(AND(AG21=1,OR(F21="ж/д",F21="авиа")),AG21*AI21,0)),"") -> 0
B22: Ласточкина Наталья Михайловна | C22: =IFERROR(VLOOKUP(B22,Инфо!$A$2:$E$89,4,0),"") -> Волжский | D22: =IFERROR(VLOOKUP($B22,Инфо!$A$3:$E$91,5,0),"") -> Медицинский представитель ОТС | E22: =IFERROR(IF(B22=0,"",IF(O22=U22,CONCATENATE(O22," ",VLOOKUP($A$1,Инфо!$K:$M,3,0)),CONCATENATE(O22,"-",U22," ",VLOOKUP($A$1,Инфо!$K:$M,3,0)))),"") -> 25 декабря | F22: авто | G22: Чебоксары - Канаш - Чебоксары | H22: =IF(F22="авто",VLOOKUP(G22,'Расстояние между городами'!C:D,2,0),"") -> 164 | I22: 12 | L22: выполнение плана 4Q | M22: выполнение плана 4Q | N22: выполнение плана 4Q | O22: 25 | P22: 0.33333333 | Q22: 25 | R22: 0.375 | S22: 25 | T22: 0.66666667 | U22: 25 | V22: 0.75 | AG22: =IF(V22=0,"",AH22+1) -> 1 | AH22: =U22-O22 -> 0 | AI22: =IFERROR(IF(AG22=0,"",VLOOKUP($D22,Суточные!$A$2:$C$13,3,0)),"") -> 1700 | AJ22: =IFERROR(IF(AG22>1,AG22*AI22,IF(AND(AG22=1,OR(F22="ж/д",F22="авиа")),AG22*AI22,0)),"") -> 0
B23: Лысова Ольга Павловна | C23: =IFERROR(VLOOKUP(B23,Инфо!$A$2:$E$89,4,0),"") -> Сибирский | D23: =IFERROR(VLOOKUP($B23,Инфо!$A$3:$E$91,5,0),"") -> Медицинский представитель ОТС | E23: =IFERROR(IF(B23=0,"",IF(O23=U23,CONCATENATE(O23," ",VLOOKUP($A$1,Инфо!$K:$M,3,0)),CONCATENATE(O23,"-",U23," ",VLOOKUP($A$1,Инфо!$K:$M,3,0)))),"") -> 8-9 декабря | F23: авто | G23: Кемерово- Белово- Ленинск-Кузнецкий-Кемерово | H23: =IF(F23="авто",VLOOKUP(G23,'Расстояние между городами'!C:D,2,0),"") -> 295 | I23: 16 | J23: Согласовано | K23: Согласовано | L23: выполнение плана 4Q | M23: посещение аптек АКБ | N23: выполнение плана 4Q | O23: 8 | P23: 0.375 | Q23: 8 | R23: 0.45833333 | S23: 9 | T23: 0.70833333 | U23: 9 | V23: 0.79166667 | X23: Да | Y23: Белово | Z23: Астра | AG23: =IF(V23=0,"",AH23+1) -> 2 | AH23: =U23-O23 -> 1 | AI23: =IFERROR(IF(AG23=0,"",VLOOKUP($D23,Суточные!$A$2:$C$13,3,0)),"") -> 1700 | AJ23: =IFERROR(IF(AG23>1,AG23*AI23,IF(AND(AG23=1,OR(F23="ж/д",F23="авиа")),AG23*AI23,0)),"") -> 3400
B24: Лысова Ольга Павловна | C24: =IFERROR(VLOOKUP(B24,Инфо!$A$2:$E$89,4,0),"") -> Сибирский | D24: =IFERROR(VLOOKUP($B24,Инфо!$A$3:$E$91,5,0),"") -> Медицинский представитель ОТС | E24: =IFERROR(IF(B24=0,"",IF(O24=U24,CONCATENATE(O24," ",VLOOKUP($A$1,Инфо!$K:$M,3,0)),CONCATENATE(O24,"-",U24," ",VLOOKUP($A$1,Инфо!$K:$M,3,0)))),"") -> 22-23 декабря | F24: авто | G24: Кемерово- Белово- Ленинск-Кузнецкий-Кемерово | H24: =IF(F24="авто",VLOOKUP(G24,'Расстояние между городами'!C:D,2,0),"") -> 295 | I24: 14 | J24: Согласовано | K24: Согласовано | L24: выполнение плана 4Q | M24: посещение аптек АКБ | N24: выполнение плана 4Q | O24: 22 | P24: 0.375 | Q24: 22 | R24: 0.45833333 | S24: 23 | T24: 0.70833333 | U24: 23 | V24: 0.79166667 | X24: Да | Y24: Белово | Z24: Астра | AG24: =IF(V24=0,"",AH24+1) -> 2 | AH24: =U24-O24 -> 1 | AI24: =IFERROR(IF(AG24=0,"",VLOOKUP($D24,Суточные!$A$2:$C$13,3,0)),"") -> 1700 | AJ24: =IFERROR(IF(AG24>1,AG24*AI24,IF(AND(AG24=1,OR(F24="ж/д",F24="авиа")),AG24*AI24,0)),"") -> 3400
B25: Золотухина Елена Владимировна | C25: =IFERROR(VLOOKUP(B25,Инфо!$A$2:$E$89,4,0),"") -> Волжский | D25: =IFERROR(VLOOKUP($B25,Инфо!$A$3:$E$91,5,0),"") -> Медицинский представитель ОТС | E25: =IFERROR(IF(B25=0,"",IF(O25=U25,CONCATENATE(O25," ",VLOOKUP($A$1,Инфо!$K:$M,3,0)),CONCATENATE(O25,"-",U25," ",VLOOKUP($A$1,Инфо!$K:$M,3,0)))),"") -> 2 декабря | F25: авто | G25: Оренбург - Соль-Илецк - Оренбург | H25: =IF(F25="авто",VLOOKUP(G25,'Расстояние между городами'!C:D,2,0),"") -> 146 | I25: 12 | L25: выполнение плана 4Q | M25: выполнение плана 4Q | N25: выполнение плана 4Q | O25: 2 | P25: 0.375 | Q25: 2 | R25: 0.45833333 | S25: 2 | T25: 0.70833333 | U25: 2 | V25: 0.79166667 | AG25: =IF(V25=0,"",AH25+1) -> 1 | AH25: =U25-O25 -> 0 | AI25: =IFERROR(IF(AG25=0,"",VLOOKUP($D25,Суточные!$A$2:$C$13,3,0)),"") -> 1700 | AJ25: =IFERROR(IF(AG25>1,AG25*AI25,IF(AND(AG25=1,OR(F25="ж/д",F25="авиа")),AG25*AI25,0)),"") -> 0
B26: Золотухина Елена Владимировна | C26: =IFERROR(VLOOKUP(B26,Инфо!$A$2:$E$89,4,0),"") -> Волжский | D26: =IFERROR(VLOOKUP($B26,Инфо!$A$3:$E$91,5,0),"") -> Медицинский представитель ОТС | E26: =IFERROR(IF(B26=0,"",IF(O26=U26,CONCATENATE(O26," ",VLOOKUP($A$1,Инфо!$K:$M,3,0)),CONCATENATE(O26,"-",U26," ",VLOOKUP($A$1,Инфо!$K:$M,3,0)))),"") -> 4 декабря | F26: авто | G26: Оренбург - Саракташ - Оренбург | H26: =IF(F26="авто",VLOOKUP(G26,'Расстояние между городами'!C:D,2,0),"") -> 191 | I26: 14 | L26: выполнение плана 4Q | M26: выполнение плана 4Q | N26: выполнение плана 4Q | O26: 4 | P26: 0.375 | Q26: 4 | R26: 0.45833333 | S26: 4 | T26: 0.70833333 | U26: 4 | V26: 0.79166667 | AG26: =IF(V26=0,"",AH26+1) -> 1 | AH26: =U26-O26 -> 0 | AI26: =IFERROR(IF(AG26=0,"",VLOOKUP($D26,Суточные!$A$2:$C$13,3,0)),"") -> 1700 | AJ26: =IFERROR(IF(AG26>1,AG26*AI26,IF(AND(AG26=1,OR(F26="ж/д",F26="авиа")),AG26*AI26,0)),"") -> 0
B27: Золотухина Елена Владимировна | C27: =IFERROR(VLOOKUP(B27,Инфо!$A$2:$E$89,4,0),"") -> Волжский | D27: =IFERROR(VLOOKUP($B27,Инфо!$A$3:$E$91,5,0),"") -> Медицинский представитель ОТС | E27: =IFERROR(IF(B27=0,"",IF(O27=U27,CONCATENATE(O27," ",VLOOKUP($A$1,Инфо!$K:$M,3,0)),CONCATENATE(O27,"-",U27," ",VLOOKUP($A$1,Инфо!$K:$M,3,0)))),"") -> 18-19 декабря | F27: авто | G27: Оренбург - Сорочинск- Бузулук - Оренбург | H27: =IF(F27="авто",VLOOKUP(G27,'Расстояние между городами'!C:D,2,0),"") -> 510 | I27: 24 | L27: выполнение плана 4Q | M27: выполнение плана 4Q | N27: выполнение плана 4Q | O27: 18 | P27: 0.375 | Q27: 18 | R27: 0.45833333 | S27: 19 | T27: 0.70833333 | U27: 19 | V27: 0.79166667 | X27: да | Y27: Бузулук | AG27: =IF(V27=0,"",AH27+1) -> 2 | AH27: =U27-O27 -> 1 | AI27: =IFERROR(IF(AG27=0,"",VLOOKUP($D27,Суточные!$A$2:$C$13,3,0)),"") -> 1700 | AJ27: =IFERROR(IF(AG27>1,AG27*AI27,IF(AND(AG27=1,OR(F27="ж/д",F27="авиа")),AG27*AI27,0)),"") -> 3400
B28: Золотухина Елена Владимировна | C28: =IFERROR(VLOOKUP(B28,Инфо!$A$2:$E$89,4,0),"") -> Волжский | D28: =IFERROR(VLOOKUP($B28,Инфо!$A$3:$E$91,5,0),"") -> Медицинский представитель ОТС | E28: =IFERROR(IF(B28=0,"",IF(O28=U28,CONCATENATE(O28," ",VLOOKUP($A$1,Инфо!$K:$M,3,0)),CONCATENATE(O28,"-",U28," ",VLOOKUP($A$1,Инфо!$K:$M,3,0)))),"") -> 23 декабря | F28: авто | G28: Оренбург - Пос. Каргала- Переволоцкий-Новосергиевка - Оренбург | H28: =IF(F28="авто",VLOOKUP(G28,'Расстояние между городами'!C:D,2,0),"") -> 250 | I28: 14 | L28: выполнение плана 4Q | M28: выполнение плана 4Q | N28: выполнение плана 4Q | O28: 23 | P28: 0.375 | Q28: 23 | R28: 0.45833333 | S28: 23 | T28: 0.70833333 | U28: 23 | V28: 0.79166667 | AG28: =IF(V28=0,"",AH28+1) -> 1 | AH28: =U28-O28 -> 0 | AI28: =IFERROR(IF(AG28=0,"",VLOOKUP($D28,Суточные!$A$2:$C$13,3,0)),"") -> 1700 | AJ28: =IFERROR(IF(AG28>1,AG28*AI28,IF(AND(AG28=1,OR(F28="ж/д",F28="авиа")),AG28*AI28,0)),"") -> 0
B29: Золотухина Елена Владимировна | C29: =IFERROR(VLOOKUP(B29,Инфо!$A$2:$E$89,4,0),"") -> Волжский | D29: =IFERROR(VLOOKUP($B29,Инфо!$A$3:$E$91,5,0),"") -> Медицинский представитель ОТС | E29: =IFERROR(IF(B29=0,"",IF(O29=U29,CONCATENATE(O29," ",VLOOKUP($A$1,Инфо!$K:$M,3,0)),CONCATENATE(O29,"-",U29," ",VLOOKUP($A$1,Инфо!$K:$M,3,0)))),"") -> 25 декабря | F29: авто | G29: Оренбург - Сакмара - Октябрьское - Оренбург | H29: =IF(F29="авто",VLOOKUP(G29,'Расстояние между городами'!C:D,2,0),"") -> 170 | I29: 14 | L29: выполнение плана 4Q | M29: выполнение плана 4Q | N29: выполнение плана 4Q | O29: 25 | P29: 0.375 | Q29: 25 | R29: 0.45833333 | S29: 25 | T29: 0.70833333 | U29: 25 | V29: 0.79166667 | AG29: =IF(V29=0,"",AH29+1) -> 1 | AH29: =U29-O29 -> 0 | AI29: =IFERROR(IF(AG29=0,"",VLOOKUP($D29,Суточные!$A$2:$C$13,3,0)),"") -> 1700 | AJ29: =IFERROR(IF(AG29>1,AG29*AI29,IF(AND(AG29=1,OR(F29="ж/д",F29="авиа")),AG29*AI29,0)),"") -> 0
B30: Ермолаева Наталья Николаевна | C30: =IFERROR(VLOOKUP(B30,Инфо!$A$2:$E$89,4,0),"") -> Волжский | D30: =IFERROR(VLOOKUP($B30,Инфо!$A$3:$E$91,5,0),"") -> Медицинский представитель ОТС | E30: =IFERROR(IF(B30=0,"",IF(O30=U30,CONCATENATE(O30," ",VLOOKUP($A$1,Инфо!$K:$M,3,0)),CONCATENATE(O30,"-",U30," ",VLOOKUP($A$1,Инфо!$K:$M,3,0)))),"") -> 4 декабря | F30: авто | G30: Самара - Жигулёвск - Самара | H30: =IF(F30="авто",VLOOKUP(G30,'Расстояние между городами'!C:D,2,0),"") -> 178 | I30: 14 | L30: выполнение плана 4Q | M30: выполнение плана 4Q | N30: выполнение плана 4Q | O30: 4 | P30: 0.33333333 | Q30: 4 | R30: 0.375 | S30: 4 | T30: 0.70833333 | U30: 4 | V30: 0.79166667 | AG30: =IF(V30=0,"",AH30+1) -> 1 | AH30: =U30-O30 -> 0 | AI30: =IFERROR(IF(AG30=0,"",VLOOKUP($D30,Суточные!$A$2:$C$13,3,0)),"") -> 1700 | AJ30: =IFERROR(IF(AG30>1,AG30*AI30,IF(AND(AG30=1,OR(F30="ж/д",F30="авиа")),AG30*AI30,0)),"") -> 0
B31: Ермолаева Наталья Николаевна | C31: =IFERROR(VLOOKUP(B31,Инфо!$A$2:$E$89,4,0),"") -> Волжский | D31: =IFERROR(VLOOKUP($B31,Инфо!$A$3:$E$91,5,0),"") -> Медицинский представитель ОТС | E31: =IFERROR(IF(B31=0,"",IF(O31=U31,CONCATENATE(O31," ",VLOOKUP($A$1,Инфо!$K:$M,3,0)),CONCATENATE(O31,"-",U31," ",VLOOKUP($A$1,Инфо!$K:$M,3,0)))),"") -> 11 декабря | F31: авто | G31: Самара - Тольятти - Самара | H31: =IF(F31="авто",VLOOKUP(G31,'Расстояние между городами'!C:D,2,0),"") -> 177 | I31: 14 | L31: выполнение плана 4Q | M31: выполнение плана 4Q | N31: выполнение плана 4Q | O31: 11 | P31: 0.33333333 | Q31: 11 | R31: 0.375 | S31: 11 | T31: 0.70833333 | U31: 11 | V31: 0.79166667 | AG31: =IF(V31=0,"",AH31+1) -> 1 | AH31: =U31-O31 -> 0 | AI31: =IFERROR(IF(AG31=0,"",VLOOKUP($D31,Суточные!$A$2:$C$13,3,0)),"") -> 1700 | AJ31: =IFERROR(IF(AG31>1,AG31*AI31,IF(AND(AG31=1,OR(F31="ж/д",F31="авиа")),AG31*AI31,0)),"") -> 0
B32: Ермолаева Наталья Николаевна | C32: =IFERROR(VLOOKUP(B32,Инфо!$A$2:$E$89,4,0),"") -> Волжский | D32: =IFERROR(VLOOKUP($B32,Инфо!$A$3:$E$91,5,0),"") -> Медицинский представитель ОТС | E32: =IFERROR(IF(B32=0,"",IF(O32=U32,CONCATENATE(O32," ",VLOOKUP($A$1,Инфо!$K:$M,3,0)),CONCATENATE(O32,"-",U32," ",VLOOKUP($A$1,Инфо!$K:$M,3,0)))),"") -> 18 декабря | F32: авто | G32: Самара - Жигулёвск - Самара | H32: =IF(F32="авто",VLOOKUP(G32,'Расстояние между городами'!C:D,2,0),"") -> 178 | I32: 14 | L32: выполнение плана 4Q | M32: выполнение плана 4Q | N32: выполнение плана 4Q | O32: 18 | P32: 0.33333333 | Q32: 18 | R32: 0.375 | S32: 18 | T32: 0.70833333 | U32: 18 | V32: 0.79166667 | AG32: =IF(V32=0,"",AH32+1) -> 1 | AH32: =U32-O32 -> 0 | AI32: =IFERROR(IF(AG32=0,"",VLOOKUP($D32,Суточные!$A$2:$C$13,3,0)),"") -> 1700 | AJ32: =IFERROR(IF(AG32>1,AG32*AI32,IF(AND(AG32=1,OR(F32="ж/д",F32="авиа")),AG32*AI32,0)),"") -> 0
B33: Ермолаева Наталья Николаевна | C33: =IFERROR(VLOOKUP(B33,Инфо!$A$2:$E$89,4,0),"") -> Волжский | D33: =IFERROR(VLOOKUP($B33,Инфо!$A$3:$E$91,5,0),"") -> Медицинский представитель ОТС | E33: =IFERROR(IF(B33=0,"",IF(O33=U33,CONCATENATE(O33," ",VLOOKUP($A$1,Инфо!$K:$M,3,0)),CONCATENATE(O33,"-",U33," ",VLOOKUP($A$1,Инфо!$K:$M,3,0)))),"") -> 24 декабря | F33: авто | G33: Самара - Тольятти - Самара | H33: =IF(F33="авто",VLOOKUP(G33,'Расстояние между городами'!C:D,2,0),"") -> 177 | I33: 14 | L33: выполнение плана 4Q | M33: выполнение плана 4Q | N33: выполнение плана 4Q | O33: 24 | P33: 0.33333333 | Q33: 24 | R33: 0.375 | S33: 24 | T33: 0.70833333 | U33: 24 | V33: 0.79166667 | AG33: =IF(V33=0,"",AH33+1) -> 1 | AH33: =U33-O33 -> 0 | AI33: =IFERROR(IF(AG33=0,"",VLOOKUP($D33,Суточные!$A$2:$C$13,3,0)),"") -> 1700 | AJ33: =IFERROR(IF(AG33>1,AG33*AI33,IF(AND(AG33=1,OR(F33="ж/д",F33="авиа")),AG33*AI33,0)),"") -> 0
B34: Сабурова Ирина Андреевна | C34: =IFERROR(VLOOKUP(B34,Инфо!$A$2:$E$89,4,0),"") -> Волжский | D34: =IFERROR(VLOOKUP($B34,Инфо!$A$3:$E$91,5,0),"") -> Медицинский представитель ОТС | E34: =IFERROR(IF(B34=0,"",IF(O34=U34,CONCATENATE(O34," ",VLOOKUP($A$1,Инфо!$K:$M,3,0)),CONCATENATE(O34,"-",U34," ",VLOOKUP($A$1,Инфо!$K:$M,3,0)))),"") -> 11 декабря | F34: авто | G34: Екатеринбург - Большое Седельниково-Первомайский-Октябрьский-Кашино-Сысерть-Щелкун-Бобровский - Екатеринбург | H34: =IF(F34="авто",VLOOKUP(G34,'Расстояние между городами'!C:D,2,0),"") -> 194 | I34: 12 | L34: выполнение плана 4Q | M34: выполнение плана 4Q | N34: выполнение плана 4Q | O34: 11 | P34: 0.33333333 | Q34: 11 | R34: 0.375 | S34: 11 | T34: 0.70833333 | U34: 11 | V34: 0.75 | AG34: =IF(V34=0,"",AH34+1) -> 1 | AH34: =U34-O34 -> 0 | AI34: =IFERROR(IF(AG34=0,"",VLOOKUP($D34,Суточные!$A$2:$C$13,3,0)),"") -> 1700 | AJ34: =IFERROR(IF(AG34>1,AG34*AI34,IF(AND(AG34=1,OR(F34="ж/д",F34="авиа")),AG34*AI34,0)),"") -> 0
B35: Сабурова Ирина Андреевна | C35: =IFERROR(VLOOKUP(B35,Инфо!$A$2:$E$89,4,0),"") -> Волжский | D35: =IFERROR(VLOOKUP($B35,Инфо!$A$3:$E$91,5,0),"") -> Медицинский представитель ОТС | E35: =IFERROR(IF(B35=0,"",IF(O35=U35,CONCATENATE(O35," ",VLOOKUP($A$1,Инфо!$K:$M,3,0)),CONCATENATE(O35,"-",U35," ",VLOOKUP($A$1,Инфо!$K:$M,3,0)))),"") -> 25 декабря | F35: авто | G35: Екатеринбург - Большое Седельниково-Первомайский-Октябрьский-Кашино-Сысерть-Щелкун-Бобровский - Екатеринбург | H35: =IF(F35="авто",VLOOKUP(G35,'Расстояние между городами'!C:D,2,0),"") -> 194 | I35: 12 | L35: выполнение плана 4Q | M35: выполнение плана 4Q | N35: выполнение плана 4Q | O35: 25 | P35: 0.33333333 | Q35: 25 | R35: 0.375 | S35: 25 | T35: 0.70833333 | U35: 25 | V35: 0.75 | AG35: =IF(V35=0,"",AH35+1) -> 1 | AH35: =U35-O35 -> 0 | AI35: =IFERROR(IF(AG35=0,"",VLOOKUP($D35,Суточные!$A$2:$C$13,3,0)),"") -> 1700 | AJ35: =IFERROR(IF(AG35>1,AG35*AI35,IF(AND(AG35=1,OR(F35="ж/д",F35="авиа")),AG35*AI35,0)),"") -> 0
B36: Подсевалов Павел Валерьевич | C36: =IFERROR(VLOOKUP(#REF!,Инфо!$A$2:$E$89,4,0),"") | D36: =IFERROR(VLOOKUP(#REF!,Инфо!$A$3:$E$91,5,0),"") | F36: авто | G36: Новокузнецк - Осинники - Калтан - Новокузнецк | H36: =IF(F36="авто",VLOOKUP(G36,'Расстояние между городами'!C:D,2,0),"") -> 92 | I36: 14 | L36: выполнение плана 4Q | M36: выполнение плана 4Q | N36: выполнение плана 4Q | O36: 2 | P36: 0.33333333 | Q36: 2 | R36: 0.375 | S36: 2 | T36: 0.70833333 | U36: 2 | V36: 0.75 | AG36: =IF(V36=0,"",AH36+1) -> 1 | AH36: =U36-O36 -> 0 | AI36: =IFERROR(IF(AG36=0,"",VLOOKUP($D36,Суточные!$A$2:$C$13,3,0)),"") | AJ36: =IFERROR(IF(AG36>1,AG36*AI36,IF(AND(AG36=1,OR(F36="ж/д",F36="авиа")),AG36*AI36,0)),"") -> 0
B37: Подсевалов Павел Валерьевич | C37: =IFERROR(VLOOKUP(B36,Инфо!$A$2:$E$89,4,0),"") -> Сибирский | D37: =IFERROR(VLOOKUP($B36,Инфо!$A$3:$E$91,5,0),"") -> Медицинский представитель ОТС | E37: =IFERROR(IF(B36=0,"",IF(O37=U37,CONCATENATE(O37," ",VLOOKUP($A$1,Инфо!$K:$M,3,0)),CONCATENATE(O37,"-",U37," ",VLOOKUP($A$1,Инфо!$K:$M,3,0)))),"") -> 5 декабря | F37: авто | G37: Новокузнецк - Междуреченск - Мыски - Новокузнецк | H37: =IF(F37="авто",VLOOKUP(G37,'Расстояние между городами'!C:D,2,0),"") -> 157 | I37: 12 | L37: выполнение плана 4Q | M37: выполнение плана 4Q | N37: выполнение плана 4Q | O37: 5 | P37: 0.33333333 | Q37: 5 | R37: 0.375 | S37: 5 | T37: 0.70833333 | U37: 5 | V37: 0.75 | AG37: =IF(V37=0,"",AH37+1) -> 1 | AH37: =U37-O37 -> 0 | AI37: =IFERROR(IF(AG37=0,"",VLOOKUP($D37,Суточные!$A$2:$C$13,3,0)),"") -> 1700 | AJ37: =IFERROR(IF(AG37>1,AG37*AI37,IF(AND(AG37=1,OR(F37="ж/д",F37="авиа")),AG37*AI37,0)),"") -> 0
B38: Подсевалов Павел Валерьевич | C38: =IFERROR(VLOOKUP(B38,Инфо!$A$2:$E$89,4,0),"") -> Сибирский | D38: =IFERROR(VLOOKUP($B38,Инфо!$A$3:$E$91,5,0),"") -> Медицинский представитель ОТС | E38: =IFERROR(IF(B38=0,"",IF(O38=U38,CONCATENATE(O38," ",VLOOKUP($A$1,Инфо!$K:$M,3,0)),CONCATENATE(O38,"-",U38," ",VLOOKUP($A$1,Инфо!$K:$M,3,0)))),"") -> 8 декабря | F38: авто | G38: Новокузнецк - Киселёвск - Новокузнецк | H38: =IF(F38="авто",VLOOKUP(G38,'Расстояние между городами'!C:D,2,0),"") -> 120 | I38: 12 | L38: выполнение плана 4Q | M38: выполнение плана 4Q | N38: выполнение плана 4Q | O38: 8 | P38: 0.33333333 | Q38: 8 | R38: 0.375 | S38: 8 | T38: 0.70833333 | U38: 8 | V38: 0.75 | AG38: =IF(V38=0,"",AH38+1) -> 1 | AH38: =U38-O38 -> 0 | AI38: =IFERROR(IF(AG38=0,"",VLOOKUP($D38,Суточные!$A$2:$C$13,3,0)),"") -> 1700 | AJ38: =IFERROR(IF(AG38>1,AG38*AI38,IF(AND(AG38=1,OR(F38="ж/д",F38="авиа")),AG38*AI38,0)),"") -> 0
B39: Подсевалов Павел Валерьевич | C39: =IFERROR(VLOOKUP(B39,Инфо!$A$2:$E$89,4,0),"") -> Сибирский | D39: =IFERROR(VLOOKUP($B39,Инфо!$A$3:$E$91,5,0),"") -> Медицинский представитель ОТС | E39: =IFERROR(IF(B39=0,"",IF(O39=U39,CONCATENATE(O39," ",VLOOKUP($A$1,Инфо!$K:$M,3,0)),CONCATENATE(O39,"-",U39," ",VLOOKUP($A$1,Инфо!$K:$M,3,0)))),"") -> 9 декабря | F39: авто | G39: Новокузнецк - Киселёвск - Прокопьевск - Новокузнецк | H39: =IF(F39="авто",VLOOKUP(G39,'Расстояние между городами'!C:D,2,0),"") -> 118 | I39: 16 | L39: выполнение плана 4Q | M39: выполнение плана 4Q | N39: выполнение плана 4Q | O39: 9 | P39: 0.33333333 | Q39: 9 | R39: 0.375 | S39: 9 | T39: 0.70833333 | U39: 9 | V39: 0.75 | AG39: =IF(V39=0,"",AH39+1) -> 1 | AH39: =U39-O39 -> 0 | AI39: =IFERROR(IF(AG39=0,"",VLOOKUP($D39,Суточные!$A$2:$C$13,3,0)),"") -> 1700 | AJ39: =IFERROR(IF(AG39>1,AG39*AI39,IF(AND(AG39=1,OR(F39="ж/д",F39="авиа")),AG39*AI39,0)),"") -> 0
B40: Подсевалов Павел Валерьевич | C40: =IFERROR(VLOOKUP(B40,Инфо!$A$2:$E$89,4,0),"") -> Сибирский | D40: =IFERROR(VLOOKUP($B40,Инфо!$A$3:$E$91,5,0),"") -> Медицинский представитель ОТС | E40: =IFERROR(IF(B40=0,"",IF(O40=U40,CONCATENATE(O40," ",VLOOKUP($A$1,Инфо!$K:$M,3,0)),CONCATENATE(O40,"-",U40," ",VLOOKUP($A$1,Инфо!$K:$M,3,0)))),"") -> 12 декабря | F40: авто | G40: Новокузнецк - Междуреченск - Новокузнецк | H40: =IF(F40="авто",VLOOKUP(G40,'Расстояние между городами'!C:D,2,0),"") -> 157 | I40: 12 | L40: выполнение плана 4Q | M40: выполнение плана 4Q | N40: выполнение плана 4Q | O40: 12 | P40: 0.33333333 | Q40: 12 | R40: 0.375 | S40: 12 | T40: 0.70833333 | U40: 12 | V40: 0.75 | AG40: =IF(V40=0,"",AH40+1) -> 1 | AH40: =U40-O40 -> 0 | AI40: =IFERROR(IF(AG40=0,"",VLOOKUP($D40,Суточные!$A$2:$C$13,3,0)),"") -> 1700 | AJ40: =IFERROR(IF(AG40>1,AG40*AI40,IF(AND(AG40=1,OR(F40="ж/д",F40="авиа")),AG40*AI40,0)),"") -> 0
...

Sheet Свод для печати
A1: ="План командировок Отдела продаж МП "&VLOOKUP('Отдел Продаж МП '!A1,Инфо!K:L,2,0)&"-"&TEXT(TODAY(),"yy") -> План командировок Отдела продаж МП Дек-yy
A2: согласование от ДП | B2: Согласовано
A4: Фамилия Имя | B4: Регион | C4: Срок командировки | D4: Город проживания-Город командировок-Город проживания | E4: Транспорт (Авиа, Ж/д, авто) | F4: Итог суточные,руб.
A5: Кузнецова Марина Борисовна | B5: Сибирский | C5: 12 декабря | D5: Иркутск - Хомутово-Урик - Иркутск | E5: авто | F5: 0
C6: 22 декабря | D6: Иркутск - Ангарск - Усолье-Сибирское - Иркутск | E6: авто | F6: 0
C7: 23 декабря | D7: Иркутск - Шелехов - Иркутск | E7: авто | F7: 0
C8: 26 декабря | D8: Иркутск - Хомутово-Урик - Иркутск | E8: авто | F8: 0
C9: 8 декабря | D9: Иркутск - Ангарск - Усолье-Сибирское - Иркутск | E9: авто | F9: 0
C10: 9 декабря | D10: Иркутск - Шелехов - Иркутск | E10: авто | F10: 0
A11: Кузнецова Марина Борисовна Итог | F11: 0
A12: Лысова Ольга Павловна | B12: Сибирский | C12: 22-23 декабря | D12: Кемерово- Белово- Ленинск-Кузнецкий-Кемерово | E12: авто | F12: 3400
C13: 8-9 декабря | D13: Кемерово- Белово- Ленинск-Кузнецкий-Кемерово | E13: авто | F13: 3400
A14: Лысова Ольга Павловна Итог | F14: 6800
A15: Молчанова Надежда Николаевна | B15: Сибирский | C15: 9-11 декабря | D15: Барнаул - Бийск - Барнаул | E15: авто | F15: 5100
A16: Молчанова Надежда Николаевна Итог | F16: 5100
A17: Общий итог | F17: 11900

Sheet Расстояние между городами
A1: Город базирования | B1: Город назначения | C1: маршрут | D1: Км туда и обратно
A2: Архангельск | B2: Новодвинск | C2: =CONCATENATE(A2," - ",B2," - ",A2) -> Архангельск - Новодвинск - Архангельск | D2: 52
A3: Архангельск | B3: Северодвинск | C3: =CONCATENATE(A3," - ",B3," - ",A3) -> Архангельск - Северодвинск - Архангельск | D3: 88
A4: Балашиха | B4: Воскресенск | C4: =CONCATENATE(A4," - ",B4," - ",A4) -> Балашиха - Воскресенск - Балашиха | D4: 199
A5: Балашиха | B5: Шатура | C5: =CONCATENATE(A5," - ",B5," - ",A5) -> Балашиха - Шатура - Балашиха | D5: 245
A6: Барнаул | B6: Заринск | C6: =CONCATENATE(A6," - ",B6," - ",A6) -> Барнаул - Заринск - Барнаул | D6: 228
A7: Барнаул | B7: Бийск | C7: =CONCATENATE(A7," - ",B7," - ",A7) -> Барнаул - Бийск - Барнаул | D7: 319
A8: Барнаул | B8: Бийск - Заринск | C8: =CONCATENATE(A8," - ",B8," - ",A8) -> Барнаул - Бийск - Заринск - Барнаул | D8: 442
A9: Барнаул | B9: Новоалтайск | C9: =CONCATENATE(A9," - ",B9," - ",A9) -> Барнаул - Новоалтайск - Барнаул | D9: 33
A10: Белгород | B10: Борисовка | C10: =CONCATENATE(A10," - ",B10," - ",A10) -> Белгород - Борисовка - Белгород | D10: 96
A11: Белгород | B11: Борисовка -Томаровка | C11: =CONCATENATE(A11," - ",B11," - ",A11) -> Белгород - Борисовка -Томаровка - Белгород | D11: 99
A12: Белгород | B12: Ивня - Ракитное | C12: =CONCATENATE(A12," - ",B12," - ",A12) -> Белгород - Ивня - Ракитное - Белгород | D12: 183
A13: Белгород | B13: Ивня | C13: =CONCATENATE(A13," - ",B13," - ",A13) -> Белгород - Ивня - Белгород | D13: 155
... A49: Вологда | B49: Шексна - Череповец | C49: =CONCATENATE(A49," - ",B49," - ",A49) -> Вологда - Шексна - Череповец - Вологда | D49: 282
A50: Воронеж | B50: Стрелица-Хохольский-Латная-Семилуки-Воронеж-Землянск | C50: Воронеж-Стрелица-Хохольский-Латная-Семилуки-Землянск-Воронеж. | D50: 250
A51: Воронеж | B51: Стрелица-Хохольский-Латная-Семилуки-Воронеж | C51: Воронеж-Стрелица-Хохольский-Латная-Семилуки-Воронеж | D51: 696
A52: Воронеж | B52: Анна-Садовое-Воронеж | C52: Воронеж-Анна-Воронеж | D52: 200
A53: Воронеж | B53: Анна-Эртиль | C53: Воронеж-Анна-Эртиль-Воронеж. | D53: 270
A54: Воронеж | B54: Анна - Новохопёрск | C54: =CONCATENATE(A54," - ",B54," - ",A54) -> Воронеж - Анна - Новохопёрск - Воронеж | D54: 438
A55: Воронеж | B55: Таловая-Бутурлиновка-Воробьевка-Калач-Воронеж | C55: Воронеж-Таловая-Бутурлиновка-Воробьевка-Калач-Воронеж | D55: 550
A56: Воронеж | B56: Стрелица-Хохольский-Латная-Семилуки-Землянск | C56: Воронеж-Стрелица-Хохольский-Латная-Семилуки-Землянск-Воронеж. | D56: 160
A57: Воронеж | B57: Чертовицы-ВНИИСС-Рамонь-Ямное-Воронеж | C57: Воронеж-Чертовицы-ВНИИСС-Рамонь-Ямное-Воронеж | D57: 56
A58: Воронеж | B58: Воронеж-Новая Усмань-Орлово-Воронеж | C58: Воронеж-Новая Усмань-Орлово-Воронеж. | D58: 455
A59: Воронеж | B59: Анна - Садовое - Новохопёрск | C59: =CONCATENATE(A59," - ",B59," - ",A59) -> Воронеж - Анна - Садовое - Новохопёрск - Воронеж | D59: 450
A60: Воронеж | B60: Бутурлиновка - Калач | C60: =CONCATENATE(A60," - ",B60," - ",A60) -> Воронеж - Бутурлиновка - Калач - Воронеж | D60: 458
A61: Воронеж | B61: Девица - Стрелица - Хохольский - Латная - Семилуки | C61: =CONCATENATE(A61," - ",B61," - ",A61) -> Воронеж - Девица - Стрелица - Хохольский - Латная - Семилуки - Воронеж | D61: 89
A62: Воронеж | B62: Лиски | C62: =CONCATENATE(A62," - ",B62," - ",A62) -> Воронеж - Лиски - Воронеж | D62: 214
A63: Воронеж | B63: Нововоронеж | C63: =CONCATENATE(A63," - ",B63," - ",A63) -> Воронеж - Нововоронеж - Воронеж | D63: 90
A64: Воронеж | B64: Нововоронеж-Новая Усмань-Орлово | C64: Воронеж-Нововоронеж-Новая Усмань-Орлово-Воронеж. | D64: 140
A65: Воронеж | B65: Новая Усмань | C65: =CONCATENATE(A65," - ",B65," - ",A65) -> Воронеж - Новая Усмань - Воронеж | D65: 32
A66: Воронеж | B66: Новая Усмань - Орлово - Воля | C66: =CONCATENATE(A66," - ",B66," - ",A66) -> Воронеж - Новая Усмань - Орлово - Воля - Воронеж | D66: 77
A67: Воронеж | B67: Рамонь | C67: =CONCATENATE(A67," - ",B67," - ",A67) -> Воронеж - Рамонь - Воронеж | D67: 83
A68: Воронеж | B68: Солнечный - ВНИИСС - Рамонь - Новоживотинное - Ямное | C68: =CONCATENATE(A68," - ",B68," - ",A68) -> Воронеж - Солнечный - ВНИИСС - Рамонь - Новоживотинное - Ямное - Воронеж | D68: 87
A69: Воронеж | B69: Семилуки - Хохольский | C69: =CONCATENATE(A69," - ",B69," - ",A69) -> Воронеж - Семилуки - Хохольский - Воронеж | D69: 91
A70: Воронеж | B70: Острогожск | C70: =CONCATENATE(A70," - ",B70," - ",A70) -> Воронеж - Острогожск - Воронеж | D70: 225
A71: Воронеж | B71: Хреновое - Таловая - Бутурлиновка - Воробьевка - Калач | C71: =CONCATENATE(A71," - ",B71," - ",A71) -> Воронеж - Хреновое - Таловая - Бутурлиновка - Воробьевка - Калач - Воронеж | D71: 501
A72: Егорьевск | B72: Воскресенск | C72: =CONCATENATE(A72," - ",B72," - ",A72) -> Егорьевск - Воскресенск - Егорьевск | D72: 56
A73: Егорьевск | B73: Москва | C73: =CONCATENATE(A73," - ",B73," - ",A73) -> Егорьевск - Москва - Егорьевск | D73: 250
A74: Егорьевск | B74: Ногинск | C74: =CONCATENATE(A74," - ",B74," - ",A74) -> Егорьевск - Ногинск - Егорьевск | D74: 165
A75: Егорьевск | B75: Орехово-Зуево | C75: =CONCATENATE(A75," - ",B75," - ",A75) -> Егорьевск - Орехово-Зуево - Егорьевск | D75: 117
...

Sheet Инфо
A1: МП | B1: РД | C1: город локации | D1: регион | E1: должность | G1: Медицинский Представитель | I1: авто | K1: № месяца | L1: Месяц | M1: Род.падеж | O1: Дата | P1: Время | R1: РД | S1: Регион
A2: Баранова Лилия Борисовна | B2: Толмачева Татьяна Владимировна | C2: Омск | D2: Сибирский | E2: Медицинский представитель ОТС
A3: Грудинина Галина Сергеевна | B3: Шалыга Игорь Анатольевич | C3: Улан-Удэ | D3: Сибирский | E3: Медицинский представитель ОТС | G3: Региональный Менеджер | I3: авиа | K3: 1 | L3: Янв | M3: января | O3: 1 | P3: 0 | R3: Толмачева Татьяна Владимировна | S3: Сибирский
A4: Ермолаева Наталья Николаевна | B4: Павлуткин Сергей Евгеньевич | C4: Самара | D4: Волжский | E4: Медицинский представитель ОТС | G4: Региональный Директор | I4: ж/д | K4: 2 | L4: Фев | M4: февраля | O4: 2 | P4: 0.041666667
A5: Золотухина Елена Владимировна | B5: Русяева Юлия Александровна | C5: Оренбург | D5: Волжский | E5: Медицинский представитель ОТС | G5: Территориальный Директор | K5: 3 | L5: Мар | M5: марта | O5: 3 | P5: 0.083333333 | R5: Первакова Наталья Владимировна | S5: Южный
A6: Каневская Наталья Владимировна | B6: Павлуткин Сергей Евгеньевич | C6: Саратов | D6: Волжский | E6: Медицинский представитель ОТС | G6: Директор | K6: 5 | L6: Май | M6: мая | O6: 4 | P6: 0.16666667 | R6: Павлуткин Сергей Евгеньевич | S6: Волжский
A7: Кузнецова Марина Борисовна | B7: Толмачева Татьяна Владимировна | C7: Иркутск | D7: Сибирский | E7: Медицинский представитель ОТС | G7: Зам.директора | K7: 6 | L7: Июн | M7: июня | O7: 5 | P7: 0.20833333
A8: Котолевская Ольга Алексеевна | B8: Первакова Наталья Владимировна | C8: Ставрополь | D8: Южный | E8: Медицинский представитель ОТС | G8: Медицинский представитель ОТС | K8: 7 | L8: Июл | M8: июля | O8: 6 | P8: 0.25
A9: Коробкина Лилия Михайловна | B9: Первакова Наталья Владимировна | C9: Волгоград | D9: Южный | E9: Медицинский представитель ОТС | G9: Медицинский представитель RX | K9: 8 | L9: Авг | M9: августа | O9: 7 | P9: 0.29166667
A10: Ласточкина Наталья Михайловна | B10: Павлуткин Сергей Евгеньевич | C10: Чебоксары | D10: Волжский | E10: Медицинский представитель ОТС | K10: 9 | L10: Сен | M10: сентября | O10: 8 | P10: 0.33333333
A11: Лысова Ольга Павловна | B11: Толмачева Татьяна Владимировна | C11: Кемерово | D11: Сибирский | E11: Медицинский представитель ОТС | K11: 10 | L11: Окт | M11: октября | O11: 9 | P11: 0.375
A12: Молчанова Надежда Николаевна | B12: Толмачева Татьяна Владимировна | C12: Барнаул | D12: Сибирский | E12: Медицинский представитель ОТС | K12: 11 | L12: Ноя | M12: ноября | O12: 10 | P12: 0.41666667
A13: Пегарькова Елена Александровна | B13: Салазкин Андрей Владимирович | C13: Воронеж | D13: Управление продаж | E13: Медицинский представитель ОТС | K13: 12 | L13: Дек | M13: декабря | O13: 11 | P13: 0.45833333
A14: Пилипейко Антон Николаевич | B14: Шалыга Игорь Анатольевич | C14: Хабаровск | D14: Сибирский | E14: Медицинский представитель ОТС | O14: 12 | P14: 0.5
A15: Плешкова Елена Владимировна | B15: Салазкин Андрей Владимирович | C15: Рязань | D15: Управление продаж | E15: Медицинский представитель ОТС | O15: 13 | P15: 0.54166667
A16: Подсевалов Павел Валерьевич | B16: Толмачева Татьяна Владимировна | C16: Новокузнецк | D16: Сибирский | E16: Медицинский представитель ОТС | O16: 14 | P16: 0.58333333
A17: Романюк Марина Иосифовна | B17: Толмачева Татьяна Владимировна | C17: Омск | D17: Сибирский | E17: Медицинский представитель RX | O17: 15 | P17: 0.625
A18: Рудакова Ирина Владимировна | B18: Первакова Наталья Владимировна | C18: Краснодар | D18: Южный | E18: Медицинский представитель ОТС | O18: 16 | P18: 0.66666667
A19: Сабурова Ирина Андреевна | B19: Русяева Юлия Александровна | C19: Екатеринбург | D19: Волжский | E19: Медицинский представитель ОТС | O19: 17 | P19: 0.70833333
A20: Усачева Светлана Вадимовна | B20: Салазкин Андрей Владимирович | C20: Вологда | D20: Управление продаж | E20: Медицинский представитель ОТС | O20: 18 | P20: 0.75
A21: Устигова Надежда Геннадьевна | B21: Толмачева Татьяна Владимировна | C21: Москва | D21: Сибирский | E21: Медицинский представитель ОТС | O21: 19 | P21: 0.79166667
A22: Чураева Марина Олеговна | B22: Павлуткин Сергей Евгеньевич | C22: Пенза | D22: Волжский | E22: Медицинский представитель ОТС | O22: 20 | P22: 0.83333333
A23: Шарыпов Александр Александрович | B23: Толмачева Татьяна Владимировна | C23: Новосибирск | D23: Сибирский | E23: Медицинский представитель ОТС | O23: 21 | P23: 0.875
O24: 22 | P24: 0.91666667
O25: 23 | P25: 0.95833333
O26: 24
O27: 25
O28: 26
O29: 27
O30: 28
O31: 29
O32: 30
O33: 31

Sheet Суточные
A1: должность | B1: Проживание | C1: Суточные
A2: Медицинский Представитель Микс | B2: 4500 | C2: 1700
A3: Медицинский представитель ОТС | B3: 4500 | C3: 1700
A4: Медицинский представитель RX | B4: 4500 | C4: 1700
A5: Региональный Менеджер | B5: 5000 | C5: 1700
A6: Региональный Директор | B6: 5000 | C6: 1700
A7: Менеджер по работе с ключевыми клиентами | B7: 5500 | C7: 1700
A8: Менеджер по работе с аптечными сетями | B8: 5500 | C8: 1700
A9: Национальный менеджер по работе с аптечными сетями | B9: 5500 | C9: 1700
A10: Групп продакт менеджер | B10: 5500 | C10: 1700
A11: Бренд-менеджер | B11: 5500 | C11: 1700
A12: Зам.ком.дир. | B12: 5500 | C12: 1700
A13: Менеджер по работе с клиентами | B13: 5500 | C13: 1700
A14: Директор | B14: 6000 | C14: 1700
